<?xml version="1.0" ?>
<!-- =================================================================================== -->
<!-- |    This document was autogenerated by xacro from urdf/4wheel_output.xacro        | -->
<!-- |    EDITING THIS FILE BY HAND IS NOT RECOMMENDED                                 | -->
<!-- =================================================================================== -->
<robot xmlns:xacro="http://www.ros.org/wiki/xacro" name="4wheel_output">
  <material name="silver">
    <color rgba="0.700 0.700 0.700 1.000"/>
  </material>
  <transmission name="Revolute 1_tran">
    <type>transmission_interface/SimpleTransmission</type>
    <joint name="Revolute 1">
      <hardwareInterface>hardware_interface/EffortJointInterface</hardwareInterface>
    </joint>
    <actuator name="Revolute 1_actr">
      <hardwareInterface>hardware_interface/EffortJointInterface</hardwareInterface>
      <mechanicalReduction>1</mechanicalReduction>
    </actuator>
  </transmission>
  <transmission name="Revolute 2_tran">
    <type>transmission_interface/SimpleTransmission</type>
    <joint name="Revolute 2">
      <hardwareInterface>hardware_interface/EffortJointInterface</hardwareInterface>
    </joint>
    <actuator name="Revolute 2_actr">
      <hardwareInterface>hardware_interface/EffortJointInterface</hardwareInterface>
      <mechanicalReduction>1</mechanicalReduction>
    </actuator>
  </transmission>
  <transmission name="Revolute 6_tran">
    <type>transmission_interface/SimpleTransmission</type>
    <joint name="Revolute 6">
      <hardwareInterface>hardware_interface/EffortJointInterface</hardwareInterface>
    </joint>
    <actuator name="Revolute 6_actr">
      <hardwareInterface>hardware_interface/EffortJointInterface</hardwareInterface>
      <mechanicalReduction>1</mechanicalReduction>
    </actuator>
  </transmission>
  <transmission name="Revolute 7_tran">
    <type>transmission_interface/SimpleTransmission</type>
    <joint name="Revolute 7">
      <hardwareInterface>hardware_interface/EffortJointInterface</hardwareInterface>
    </joint>
    <actuator name="Revolute 7_actr">
      <hardwareInterface>hardware_interface/EffortJointInterface</hardwareInterface>
      <mechanicalReduction>1</mechanicalReduction>
    </actuator>
  </transmission>
  <gazebo>
    <plugin name="control" filename="libgazebo_ros_control.so"/>
  </gazebo>
  <gazebo reference="base_footprint">
    <material>Gazebo/Silver</material>
    <mu1>0.2</mu1>
    <mu2>0.2</mu2>
    <selfCollide>true</selfCollide>
    <gravity>true</gravity>
  </gazebo>
  <gazebo reference="back_left_1">
    <material>Gazebo/Silver</material>
    <mu1>0.2</mu1>
    <mu2>0.2</mu2>
    <selfCollide>true</selfCollide>
  </gazebo>
  <gazebo reference="back_right_1">
    <material>Gazebo/Silver</material>
    <mu1>0.2</mu1>
    <mu2>0.2</mu2>
    <selfCollide>true</selfCollide>
  </gazebo>
  <gazebo reference="lidar_v1_1">
    <material>Gazebo/Silver</material>
    <mu1>0.2</mu1>
    <mu2>0.2</mu2>
    <selfCollide>true</selfCollide>
  </gazebo>
  <gazebo reference="front_right_1">
    <material>Gazebo/Silver</material>
    <mu1>0.2</mu1>
    <mu2>0.2</mu2>
    <selfCollide>true</selfCollide>
  </gazebo>
  <gazebo reference="front_left_1">
    <material>Gazebo/Silver</material>
    <mu1>0.2</mu1>
    <mu2>0.2</mu2>
    <selfCollide>true</selfCollide>
  </gazebo>
  <link name="base_link">
    <inertial>
      <origin xyz="-0.03231720679873715 9.242377183249019e-06 0.050011490590469526" rpy="0 0 0"/>
      <mass value="11.13582814957309"/>
      <inertia ixx="0.069638" iyy="0.133325" izz="0.14446" ixy="1.3e-05" iyz="-4e-06" ixz="-0.010205"/>
    </inertial>
    <visual>
      <origin xyz="0 0 0" rpy="0 0 0"/>
      <geometry>
        <mesh filename="package://4wheel_output_description/meshes/base_link.stl" scale="0.001 0.001 0.001"/>
      </geometry>
      <material name="silver"/>
    </visual>
    <collision>
      <origin xyz="0 0 0" rpy="0 0 0"/>
      <geometry>
        <mesh filename="package://4wheel_output_description/meshes/base_link.stl" scale="0.001 0.001 0.001"/>
      </geometry>
    </collision>
  </link>
  <link name="back_left_1">
    <inertial>
      <origin xyz="-1.3877787807814457e-17 -0.015000000000000041 0.0" rpy="0 0 0"/>
      <mass value="1.1837521118726337"/>
      <inertia ixx="0.000562" iyy="0.000947" izz="0.000562" ixy="-0.0" iyz="-0.0" ixz="-0.0"/>
    </inertial>
    <visual>
      <origin xyz="-0.1025 0.1175 -0.0225" rpy="0 0 0"/>
      <geometry>
        <mesh filename="package://4wheel_output_description/meshes/back_left_1.stl" scale="0.001 0.001 0.001"/>
      </geometry>
      <material name="silver"/>
    </visual>
    <collision>
      <origin xyz="-0.1025 0.1175 -0.0225" rpy="0 0 0"/>
      <geometry>
        <mesh filename="package://4wheel_output_description/meshes/back_left_1.stl" scale="0.001 0.001 0.001"/>
      </geometry>
    </collision>
  </link>
  <link name="back_right_1">
    <inertial>
      <origin xyz="-2.7755575615628914e-17 0.014999999999999958 0.0" rpy="0 0 0"/>
      <mass value="1.1837521118726337"/>
      <inertia ixx="0.000562" iyy="0.000947" izz="0.000562" ixy="0.0" iyz="-0.0" ixz="0.0"/>
    </inertial>
    <visual>
      <origin xyz="-0.1025 -0.1175 -0.0225" rpy="0 0 0"/>
      <geometry>
        <mesh filename="package://4wheel_output_description/meshes/back_right_1.stl" scale="0.001 0.001 0.001"/>
      </geometry>
      <material name="silver"/>
    </visual>
    <collision>
      <origin xyz="-0.1025 -0.1175 -0.0225" rpy="0 0 0"/>
      <geometry>
        <mesh filename="package://4wheel_output_description/meshes/back_right_1.stl" scale="0.001 0.001 0.001"/>
      </geometry>
    </collision>
  </link>
  <link name="lidar_v1_1">
    <inertial>
      <origin xyz="-1.0058283789193823e-09 0.0 0.009858499938735416" rpy="0 0 0"/>
      <mass value="0.5286905929941373"/>
      <inertia ixx="0.000159" iyy="0.000159" izz="0.000284" ixy="-0.0" iyz="-0.0" ixz="0.0"/>
    </inertial>
    <visual>
      <origin xyz="0.0675 -0.0 -0.165" rpy="0 0 0"/>
      <geometry>
        <mesh filename="package://4wheel_output_description/meshes/lidar_v1_1.stl" scale="0.001 0.001 0.001"/>
      </geometry>
      <material name="silver"/>
    </visual>
    <collision>
      <origin xyz="0.0675 -0.0 -0.165" rpy="0 0 0"/>
      <geometry>
        <mesh filename="package://4wheel_output_description/meshes/lidar_v1_1.stl" scale="0.001 0.001 0.001"/>
      </geometry>
    </collision>
  </link>
  <link name="front_right_1">
    <inertial>
      <origin xyz="0.0 0.014999999999999958 0.0" rpy="0 0 0"/>
      <mass value="1.1837521118726337"/>
      <inertia ixx="0.000562" iyy="0.000947" izz="0.000562" ixy="0.0" iyz="-0.0" ixz="0.0"/>
    </inertial>
    <visual>
      <origin xyz="0.1925 -0.1175 -0.0225" rpy="0 0 0"/>
      <geometry>
        <mesh filename="package://4wheel_output_description/meshes/front_right_1.stl" scale="0.001 0.001 0.001"/>
      </geometry>
      <material name="silver"/>
    </visual>
    <collision>
      <origin xyz="0.1925 -0.1175 -0.0225" rpy="0 0 0"/>
      <geometry>
        <mesh filename="package://4wheel_output_description/meshes/front_right_1.stl" scale="0.001 0.001 0.001"/>
      </geometry>
    </collision>
  </link>
  <link name="front_left_1">
    <inertial>
      <origin xyz="0.0 -0.015000000000000041 0.0" rpy="0 0 0"/>
      <mass value="1.1837521118726337"/>
      <inertia ixx="0.000562" iyy="0.000947" izz="0.000562" ixy="0.0" iyz="-0.0" ixz="-0.0"/>
    </inertial>
    <visual>
      <origin xyz="0.1925 0.1175 -0.0225" rpy="0 0 0"/>
      <geometry>
        <mesh filename="package://4wheel_output_description/meshes/front_left_1.stl" scale="0.001 0.001 0.001"/>
      </geometry>
      <material name="silver"/>
    </visual>
    <collision>
      <origin xyz="0.1925 0.1175 -0.0225" rpy="0 0 0"/>
      <geometry>
        <mesh filename="package://4wheel_output_description/meshes/front_left_1.stl" scale="0.001 0.001 0.001"/>
      </geometry>
    </collision>
  </link>
  <joint name="Revolute 1" type="continuous">
    <origin xyz="0.1025 -0.1175 0.0225" rpy="0 0 0"/>
    <parent link="base_link"/>
    <child link="back_left_1"/>
    <axis xyz="0.0 -1.0 -0.0"/>
  </joint>
  <joint name="Revolute 2" type="continuous">
    <origin xyz="0.1025 0.1175 0.0225" rpy="0 0 0"/>
    <parent link="base_link"/>
    <child link="back_right_1"/>
    <axis xyz="0.0 1.0 -0.0"/>
  </joint>
  <joint name="Rigid 3" type="fixed">
    <origin xyz="-0.0675 0.0 0.165" rpy="0 0 0"/>
    <parent link="base_link"/>
    <child link="lidar_v1_1"/>
  </joint>
  <joint name="Revolute 6" type="continuous">
    <origin xyz="-0.1925 0.1175 0.0225" rpy="0 0 0"/>
    <parent link="base_link"/>
    <child link="front_right_1"/>
    <axis xyz="0.0 1.0 -0.0"/>
  </joint>
  <joint name="Revolute 7" type="continuous">
    <origin xyz="-0.1925 -0.1175 0.0225" rpy="0 0 0"/>
    <parent link="base_link"/>
    <child link="front_left_1"/>
    <axis xyz="-0.0 1.0 0.0"/>
  </joint>
</robot>
