<?xml version="1.0" ?>
<!-- =================================================================================== -->
<!-- |    This document was autogenerated by xacro from urdf\angle_excurate_arm_ver2.xacro.temp | -->
<!-- |    EDITING THIS FILE BY HAND IS NOT RECOMMENDED                                 | -->
<!-- =================================================================================== -->
<robot xmlns:xacro="http://www.ros.org/wiki/xacro" name="angle_excurate_arm_ver2">
  <material name="silver">
    <color rgba="0.700 0.700 0.700 1.000"/>
  </material>
  <transmission name="Revolute 1_tran">
    <type>transmission_interface/SimpleTransmission</type>
    <joint name="Revolute 1">
      <hardwareInterface>hardware_interface/EffortJointInterface</hardwareInterface>
    </joint>
    <actuator name="Revolute 1_actr">
      <hardwareInterface>hardware_interface/EffortJointInterface</hardwareInterface>
      <mechanicalReduction>1</mechanicalReduction>
    </actuator>
  </transmission>
  <transmission name="Revolute 2_tran">
    <type>transmission_interface/SimpleTransmission</type>
    <joint name="Revolute 2">
      <hardwareInterface>hardware_interface/EffortJointInterface</hardwareInterface>
    </joint>
    <actuator name="Revolute 2_actr">
      <hardwareInterface>hardware_interface/EffortJointInterface</hardwareInterface>
      <mechanicalReduction>1</mechanicalReduction>
    </actuator>
  </transmission>
  <transmission name="Revolute 3_tran">
    <type>transmission_interface/SimpleTransmission</type>
    <joint name="Revolute 3">
      <hardwareInterface>hardware_interface/EffortJointInterface</hardwareInterface>
    </joint>
    <actuator name="Revolute 3_actr">
      <hardwareInterface>hardware_interface/EffortJointInterface</hardwareInterface>
      <mechanicalReduction>1</mechanicalReduction>
    </actuator>
  </transmission>
  <transmission name="Revolute 4_tran">
    <type>transmission_interface/SimpleTransmission</type>
    <joint name="Revolute 4">
      <hardwareInterface>hardware_interface/EffortJointInterface</hardwareInterface>
    </joint>
    <actuator name="Revolute 4_actr">
      <hardwareInterface>hardware_interface/EffortJointInterface</hardwareInterface>
      <mechanicalReduction>1</mechanicalReduction>
    </actuator>
  </transmission>
  <transmission name="Revolute 5_tran">
    <type>transmission_interface/SimpleTransmission</type>
    <joint name="Revolute 5">
      <hardwareInterface>hardware_interface/EffortJointInterface</hardwareInterface>
    </joint>
    <actuator name="Revolute 5_actr">
      <hardwareInterface>hardware_interface/EffortJointInterface</hardwareInterface>
      <mechanicalReduction>1</mechanicalReduction>
    </actuator>
  </transmission>
  <transmission name="Revolute 6_tran">
    <type>transmission_interface/SimpleTransmission</type>
    <joint name="Revolute 6">
      <hardwareInterface>hardware_interface/EffortJointInterface</hardwareInterface>
    </joint>
    <actuator name="Revolute 6_actr">
      <hardwareInterface>hardware_interface/EffortJointInterface</hardwareInterface>
      <mechanicalReduction>1</mechanicalReduction>
    </actuator>
  </transmission>
  <!-- omitted .gazebo include -->
  <link name="base_link">
    <inertial>
      <origin xyz="-0.0011934057514516136 -0.001504989611362933 0.039688566141963214" rpy="0 0 0"/>
      <mass value="7.925585093654501e-07"/>
      <inertia ixx="0.0" iyy="0.0" izz="0.0" ixy="-0.0" iyz="-0.0" ixz="0.0"/>
    </inertial>
    <visual>
      <origin xyz="0 0 0" rpy="0 0 0"/>
      <geometry>
        <mesh filename="package://robot_description/meshes/base_link.stl" scale="0.001 0.001 0.001"/>
      </geometry>
      <material name="silver"/>
    </visual>
    <collision>
      <origin xyz="0 0 0" rpy="0 0 0"/>
      <geometry>
        <mesh filename="package://robot_description/meshes/base_link.stl" scale="0.001 0.001 0.001"/>
      </geometry>
    </collision>
  </link>
  <link name="base_link2_v2_1">
    <inertial>
      <origin xyz="-4.057533816860092e-07 1.764622864794483e-07 0.044844545575572145" rpy="0 0 0"/>
      <mass value="0.8724221516717809"/>
      <inertia ixx="0.000636" iyy="0.000529" izz="0.000308" ixy="0.0" iyz="0.0" ixz="0.0"/>
    </inertial>
    <visual>
      <origin xyz="0.001193 0.001505 -0.075689" rpy="0 0 0"/>
      <geometry>
        <mesh filename="package://robot_description/meshes/base_link2_v2_1.stl" scale="0.001 0.001 0.001"/>
      </geometry>
      <material name="silver"/>
    </visual>
    <collision>
      <origin xyz="0.001193 0.001505 -0.075689" rpy="0 0 0"/>
      <geometry>
        <mesh filename="package://robot_description/meshes/base_link2_v2_1.stl" scale="0.001 0.001 0.001"/>
      </geometry>
    </collision>
  </link>
  <link name="link3_v1_1">
    <inertial>
      <origin xyz="0.08484352250308666 9.052645441880343e-08 0.10111267245151587" rpy="0 0 0"/>
      <mass value="1.7894494256516058"/>
      <inertia ixx="0.00475" iyy="0.007559" izz="0.003484" ixy="-0.0" iyz="-0.0" ixz="-0.003589"/>
    </inertial>
    <visual>
      <origin xyz="0.001193 0.001505 -0.146031" rpy="0 0 0"/>
      <geometry>
        <mesh filename="package://robot_description/meshes/link3_v1_1.stl" scale="0.001 0.001 0.001"/>
      </geometry>
      <material name="silver"/>
    </visual>
    <collision>
      <origin xyz="0.001193 0.001505 -0.146031" rpy="0 0 0"/>
      <geometry>
        <mesh filename="package://robot_description/meshes/link3_v1_1.stl" scale="0.001 0.001 0.001"/>
      </geometry>
    </collision>
  </link>
  <link name="link4_v1_1">
    <inertial>
      <origin xyz="0.15672847255201927 1.1683891369164423e-08 0.010698971291654702" rpy="0 0 0"/>
      <mass value="2.6308677332376194"/>
      <inertia ixx="0.002021" iyy="0.01307" izz="0.011727" ixy="-0.0" iyz="0.0" ixz="0.000564"/>
    </inertial>
    <visual>
      <origin xyz="-0.136583 0.001505 -0.310226" rpy="0 0 0"/>
      <geometry>
        <mesh filename="package://robot_description/meshes/link4_v1_1.stl" scale="0.001 0.001 0.001"/>
      </geometry>
      <material name="silver"/>
    </visual>
    <collision>
      <origin xyz="-0.136583 0.001505 -0.310226" rpy="0 0 0"/>
      <geometry>
        <mesh filename="package://robot_description/meshes/link4_v1_1.stl" scale="0.001 0.001 0.001"/>
      </geometry>
    </collision>
  </link>
  <link name="robot_ver7_link_4_v1_1">
    <inertial>
      <origin xyz="0.01789308994980887 8.770510237987236e-09 0.0031553680758916736" rpy="0 0 0"/>
      <mass value="0.1836674229836172"/>
      <inertia ixx="9.9e-05" iyy="0.000103" izz="7.2e-05" ixy="0.0" iyz="0.0" ixz="5e-06"/>
    </inertial>
    <visual>
      <origin xyz="-0.366866 0.001505 -0.352352" rpy="0 0 0"/>
      <geometry>
        <mesh filename="package://robot_description/meshes/robot_ver7_link_4_v1_1.stl" scale="0.001 0.001 0.001"/>
      </geometry>
      <material name="silver"/>
    </visual>
    <collision>
      <origin xyz="-0.366866 0.001505 -0.352352" rpy="0 0 0"/>
      <geometry>
        <mesh filename="package://robot_description/meshes/robot_ver7_link_4_v1_1.stl" scale="0.001 0.001 0.001"/>
      </geometry>
    </collision>
  </link>
  <link name="robot_ver7_grap2_2_v1_1">
    <inertial>
      <origin xyz="0.031885243494600035 -0.005587061822560538 0.008275444275591293" rpy="0 0 0"/>
      <mass value="0.04062678364092949"/>
      <inertia ixx="4e-06" iyy="2.6e-05" izz="2.5e-05" ixy="-0.0" iyz="-0.0" ixz="-6e-06"/>
    </inertial>
    <visual>
      <origin xyz="-0.408425 0.014005 -0.35968" rpy="0 0 0"/>
      <geometry>
        <mesh filename="package://robot_description/meshes/robot_ver7_grap2_2_v1_1.stl" scale="0.001 0.001 0.001"/>
      </geometry>
      <material name="silver"/>
    </visual>
    <collision>
      <origin xyz="-0.408425 0.014005 -0.35968" rpy="0 0 0"/>
      <geometry>
        <mesh filename="package://robot_description/meshes/robot_ver7_grap2_2_v1_1.stl" scale="0.001 0.001 0.001"/>
      </geometry>
    </collision>
  </link>
  <link name="robot_ver7_grap1_2_v1_1">
    <inertial>
      <origin xyz="0.031885243494601534 0.005587079363586217 0.008275444275591237" rpy="0 0 0"/>
      <mass value="0.040626783640931655"/>
      <inertia ixx="4e-06" iyy="2.6e-05" izz="2.5e-05" ixy="0.0" iyz="0.0" ixz="-6e-06"/>
    </inertial>
    <visual>
      <origin xyz="-0.408425 -0.010995 -0.35968" rpy="0 0 0"/>
      <geometry>
        <mesh filename="package://robot_description/meshes/robot_ver7_grap1_2_v1_1.stl" scale="0.001 0.001 0.001"/>
      </geometry>
      <material name="silver"/>
    </visual>
    <collision>
      <origin xyz="-0.408425 -0.010995 -0.35968" rpy="0 0 0"/>
      <geometry>
        <mesh filename="package://robot_description/meshes/robot_ver7_grap1_2_v1_1.stl" scale="0.001 0.001 0.001"/>
      </geometry>
    </collision>
  </link>
  <link name="base_link_2_1">
    <inertial>
      <origin xyz="-4.0575332691645226e-07 1.0388637184440691e-08 -0.01005746898857467" rpy="0 0 0"/>
      <mass value="1.6067306789990348"/>
      <inertia ixx="0.003521" iyy="0.006468" izz="0.008802" ixy="0.0" iyz="-0.0" ixz="0.0"/>
    </inertial>
    <visual>
      <origin xyz="0.001193 0.001505 -0.039689" rpy="0 0 0"/>
      <geometry>
        <mesh filename="package://robot_description/meshes/base_link_2_1.stl" scale="0.001 0.001 0.001"/>
      </geometry>
      <material name="silver"/>
    </visual>
    <collision>
      <origin xyz="0.001193 0.001505 -0.039689" rpy="0 0 0"/>
      <geometry>
        <mesh filename="package://robot_description/meshes/base_link_2_1.stl" scale="0.001 0.001 0.001"/>
      </geometry>
    </collision>
  </link>
  <link name="camera_1">
    <inertial>
      <origin xyz="0.01477190606062212 3.2018043673396474e-08 0.0026049357577645482" rpy="0 0 0"/>
      <mass value="0.4003499999999954"/>
      <inertia ixx="0.000255" iyy="4.3e-05" izz="0.000271" ixy="-0.0" iyz="-0.0" ixz="-3e-06"/>
    </inertial>
    <visual>
      <origin xyz="-0.372347 0.001505 -0.274625" rpy="0 0 0"/>
      <geometry>
        <mesh filename="package://robot_description/meshes/camera_1.stl" scale="0.001 0.001 0.001"/>
      </geometry>
      <material name="silver"/>
    </visual>
    <collision>
      <origin xyz="-0.372347 0.001505 -0.274625" rpy="0 0 0"/>
      <geometry>
        <mesh filename="package://robot_description/meshes/camera_1.stl" scale="0.001 0.001 0.001"/>
      </geometry>
    </collision>
  </link>
  <link name="link3_mid_1">
    <inertial>
      <origin xyz="0.0016064696074144236 9.579573089640858e-09 0.0019153351261999574" rpy="0 0 0"/>
      <mass value="0.004162937218344747"/>
      <inertia ixx="0.0" iyy="0.0" izz="0.0" ixy="0.0" iyz="0.0" ixz="0.0"/>
    </inertial>
    <visual>
      <origin xyz="-0.144941 0.001505 -0.320186" rpy="0 0 0"/>
      <geometry>
        <mesh filename="package://robot_description/meshes/link3_mid_1.stl" scale="0.001 0.001 0.001"/>
      </geometry>
      <material name="silver"/>
    </visual>
    <collision>
      <origin xyz="-0.144941 0.001505 -0.320186" rpy="0 0 0"/>
      <geometry>
        <mesh filename="package://robot_description/meshes/link3_mid_1.stl" scale="0.001 0.001 0.001"/>
      </geometry>
    </collision>
  </link>
  <joint name="Revolute 1" type="revolute">
    <origin xyz="0.0 0.0 0.036" rpy="0 0 0"/>
    <parent link="base_link_2_1"/>
    <child link="base_link2_v2_1"/>
    <axis xyz="0.0 0.0 1.0"/>
    <limit upper="3.141593" lower="0.0" effort="100" velocity="100"/>
  </joint>
  <joint name="Revolute 2" type="revolute">
    <origin xyz="0.0 0.0 0.070342" rpy="0 0 0"/>
    <parent link="base_link2_v2_1"/>
    <child link="link3_v1_1"/>
    <axis xyz="-0.0 -1.0 0.0"/>
    <limit upper="2.094395" lower="0.0" effort="100" velocity="100"/>
  </joint>
  <joint name="Revolute 3" type="revolute">
    <origin xyz="0.137776 0.0 0.164195" rpy="0 0 0"/>
    <parent link="link3_v1_1"/>
    <child link="link4_v1_1"/>
    <axis xyz="-0.0 -1.0 0.0"/>
    <limit upper="2.617994" lower="0.0" effort="100" velocity="100"/>
  </joint>
  <joint name="Revolute 4" type="revolute">
    <origin xyz="0.230283 0.0 0.042126" rpy="0 0 0"/>
    <parent link="link4_v1_1"/>
    <child link="robot_ver7_link_4_v1_1"/>
    <axis xyz="0.984808 0.0 0.173648"/>
    <limit upper="3.141593" lower="0.0" effort="100" velocity="100"/>
  </joint>
  <joint name="Revolute 5" type="revolute">
    <origin xyz="0.041559 -0.0125 0.007328" rpy="0 0 0"/>
    <parent link="robot_ver7_link_4_v1_1"/>
    <child link="robot_ver7_grap2_2_v1_1"/>
    <axis xyz="0.173648 -0.0 -0.984808"/>
    <limit upper="1.22173" lower="0.0" effort="100" velocity="100"/>
  </joint>
  <joint name="Revolute 6" type="revolute">
    <origin xyz="0.041559 0.0125 0.007328" rpy="0 0 0"/>
    <parent link="robot_ver7_link_4_v1_1"/>
    <child link="robot_ver7_grap1_2_v1_1"/>
    <axis xyz="-0.173648 0.0 0.984808"/>
    <limit upper="1.22173" lower="0.0" effort="100" velocity="100"/>
  </joint>
  <joint name="Rigid 8" type="fixed">
    <origin xyz="-0.001193 -0.001505 0.039689" rpy="0 0 0"/>
    <parent link="base_link"/>
    <child link="base_link_2_1"/>
  </joint>
  <joint name="Rigid 11" type="fixed">
    <origin xyz="0.235764 0.0 -0.035601" rpy="0 0 0"/>
    <parent link="link4_v1_1"/>
    <child link="camera_1"/>
  </joint>
  <joint name="Rigid 12" type="fixed">
    <origin xyz="0.146134 0.0 0.174155" rpy="0 0 0"/>
    <parent link="link3_v1_1"/>
    <child link="link3_mid_1"/>
  </joint>
</robot>
